{
  "uid" : "f0a1cad6a8b028a0",
  "name" : "test_value_error[2147483648-1-multiplication]",
  "fullName" : "tests.test_functionality#test_value_error",
  "historyId" : "f318d8f8c2b09ad9b35d409463f0601e",
  "time" : {
    "start" : 1649601496808,
    "stop" : 1649601496812,
    "duration" : 4
  },
  "status" : "skipped",
  "statusMessage" : "XFAIL Ответ от сервера не соответствует ТЗ\n\nAssertionError: assert {'result': 2147483648, 'statusCode': 0} == {'statusCode': 4, 'statusMessage': 'Превышены максимальные значения параметров'}\n  Differing items:\n  {'statusCode': 0} != {'statusCode': 4}\n  Left contains 1 more item:\n  {'result': 2147483648}\n  Right contains 1 more item:\n  {'statusMessage': 'Превышены максимальные значения параметров'}\n  Full diff:\n  - {'statusCode': 4, 'statusMessage': 'Превышены максимальные значения параметров'}\n  + {'result': 2147483648, 'statusCode': 0}",
  "statusTrace" : "x = 2147483648, y = 1, task = 'multiplication'\n\n    @allure.issue(\"Bug\")\n    @allure.feature(\"ERROR=4 check\")\n    @pytest.mark.xfail(reason=\"Ответ от сервера не соответствует ТЗ\")\n    @pytest.mark.parametrize(\"task\", [\"addition\", \"multiplication\", \"division\", \"remainder\"])\n    @pytest.mark.parametrize(\"x, y\", [(-2147483649, 1), (2147483648, 1), (1, -2147483649), (1, 2147483648)])\n    def test_value_error(x, y, task):\n        respond = requests.post(f\"http://{HOST}:{PORT}/api/{task}\", json={\"x\": x, \"y\": y})\n>       assert respond.json() == {'statusCode': 4, 'statusMessage': 'Превышены максимальные значения параметров'}\nE       AssertionError: assert {'result': 2147483648, 'statusCode': 0} == {'statusCode': 4, 'statusMessage': 'Превышены максимальные значения параметров'}\nE         Differing items:\nE         {'statusCode': 0} != {'statusCode': 4}\nE         Left contains 1 more item:\nE         {'result': 2147483648}\nE         Right contains 1 more item:\nE         {'statusMessage': 'Превышены максимальные значения параметров'}\nE         Full diff:\nE         - {'statusCode': 4, 'statusMessage': 'Превышены максимальные значения параметров'}\nE         + {'result': 2147483648, 'statusCode': 0}\n\ntest_functionality.py:24: AssertionError",
  "flaky" : false,
  "newFailed" : false,
  "newBroken" : false,
  "newPassed" : false,
  "retriesCount" : 0,
  "retriesStatusChange" : false,
  "beforeStages" : [ {
    "name" : "setup_app",
    "time" : {
      "start" : 1649601435536,
      "stop" : 1649601440410,
      "duration" : 4874
    },
    "status" : "passed",
    "steps" : [ ],
    "attachments" : [ ],
    "parameters" : [ ],
    "shouldDisplayMessage" : false,
    "attachmentsCount" : 0,
    "stepsCount" : 0,
    "hasContent" : false
  } ],
  "afterStages" : [ {
    "name" : "setup_app::0",
    "time" : {
      "start" : 1649601497229,
      "stop" : 1649601499117,
      "duration" : 1888
    },
    "status" : "broken",
    "statusMessage" : "UnicodeDecodeError: 'charmap' codec can't decode byte 0x98 in position 685: character maps to <undefined>\n",
    "statusTrace" : "  File \"C:\\Users\\Oleg\\Desktop\\Study\\Test tasks\\Test_task_infotecs\\CalcAutoTest\\venv\\lib\\site-packages\\allure_commons\\_allure.py\", line 200, in __call__\n    return self._fixture_function(*args, **kwargs)\n  File \"C:\\Users\\Oleg\\Desktop\\Study\\Test tasks\\Test_task_infotecs\\CalcAutoTest\\venv\\lib\\site-packages\\_pytest\\fixtures.py\", line 899, in _teardown_yield_fixture\n    next(it)\n  File \"C:\\Users\\Oleg\\Desktop\\Study\\Test tasks\\Test_task_infotecs\\CalcAutoTest\\tests\\conftest.py\", line 23, in setup_app\n    gif = f.read()\n  File \"C:\\Users\\Oleg\\AppData\\Local\\Programs\\Python\\Python38-32\\lib\\encodings\\cp1251.py\", line 23, in decode\n    return codecs.charmap_decode(input,self.errors,decoding_table)[0]\n",
    "steps" : [ ],
    "attachments" : [ ],
    "parameters" : [ ],
    "shouldDisplayMessage" : true,
    "attachmentsCount" : 0,
    "stepsCount" : 0,
    "hasContent" : true
  } ],
  "labels" : [ {
    "name" : "feature",
    "value" : "ERROR=4 check"
  }, {
    "name" : "tag",
    "value" : "@pytest.mark.xfail(reason='Ответ от сервера не соответствует ТЗ')"
  }, {
    "name" : "parentSuite",
    "value" : "tests"
  }, {
    "name" : "suite",
    "value" : "test_functionality"
  }, {
    "name" : "host",
    "value" : "LAPTOP-60Q9K2PF"
  }, {
    "name" : "thread",
    "value" : "12828-MainThread"
  }, {
    "name" : "framework",
    "value" : "pytest"
  }, {
    "name" : "language",
    "value" : "cpython3"
  }, {
    "name" : "package",
    "value" : "tests.test_functionality"
  }, {
    "name" : "resultFormat",
    "value" : "allure2"
  } ],
  "parameters" : [ {
    "name" : "task",
    "value" : "'multiplication'"
  }, {
    "name" : "x",
    "value" : "2147483648"
  }, {
    "name" : "y",
    "value" : "1"
  } ],
  "links" : [ {
    "name" : "Bug",
    "url" : "Bug",
    "type" : "issue"
  } ],
  "hidden" : true,
  "retry" : true,
  "extra" : {
    "categories" : [ ],
    "tags" : [ "@pytest.mark.xfail(reason='Ответ от сервера не соответствует ТЗ')" ]
  },
  "source" : "f0a1cad6a8b028a0.json",
  "parameterValues" : [ "'multiplication'", "2147483648", "1" ]
}